Workbook

Sheet ملخص · Summary
A1: طلبات موقع SalesUp — لوحة سريعة
A2: الأرقام تتحدّث تلقائيًا مع كل طلب جديد يضيفه الموقع. لا تحذف الأعمدة ولا تغيّر أسماء التبويبات.
A4: النموذج / Form | B4: التبويب / Sheet | C4: إجمالي الطلبات | D4: آخر ٧ أيام | E4: اليوم | F4: آخر طلب
A5: استشارة مجانية | B5: الاستشارات · Contact | C5: =MAX(0,COUNTA('الاستشارات · Contact'!C:C)-1) | D5: =COUNTIFS('الاستشارات · Contact'!A:A,">="&TODAY()-7) | E5: =COUNTIFS('الاستشارات · Contact'!A:A,">="&TODAY()) | F5: =IF(COUNT('الاستشارات · Contact'!A:A)=0,"—",TEXT(MAX('الاستشارات · Contact'!A:A),"yyyy-mm-dd hh:mm"))
A6: طلب خدمة | B6: طلبات الخدمة · Service | C6: =MAX(0,COUNTA('طلبات الخدمة · Service'!C:C)-1) | D6: =COUNTIFS('طلبات الخدمة · Service'!A:A,">="&TODAY()-7) | E6: =COUNTIFS('طلبات الخدمة · Service'!A:A,">="&TODAY()) | F6: =IF(COUNT('طلبات الخدمة · Service'!A:A)=0,"—",TEXT(MAX('طلبات الخدمة · Service'!A:A),"yyyy-mm-dd hh:mm"))
A7: طلب مسوقين | B7: المسوقين · Marketers | C7: =MAX(0,COUNTA('المسوقين · Marketers'!C:C)-1) | D7: =COUNTIFS('المسوقين · Marketers'!A:A,">="&TODAY()-7) | E7: =COUNTIFS('المسوقين · Marketers'!A:A,">="&TODAY()) | F7: =IF(COUNT('المسوقين · Marketers'!A:A)=0,"—",TEXT(MAX('المسوقين · Marketers'!A:A),"yyyy-mm-dd hh:mm"))
A8: طلب توظيف | B8: التوظيف · Jobs | C8: =MAX(0,COUNTA('التوظيف · Jobs'!C:C)-1) | D8: =COUNTIFS('التوظيف · Jobs'!A:A,">="&TODAY()-7) | E8: =COUNTIFS('التوظيف · Jobs'!A:A,">="&TODAY()) | F8: =IF(COUNT('التوظيف · Jobs'!A:A)=0,"—",TEXT(MAX('التوظيف · Jobs'!A:A),"yyyy-mm-dd hh:mm"))
B9: الإجمالي | C9: =SUM(C5:C8) | D9: =SUM(D5:D8) | E9: =SUM(E5:E8)
A11: الخدمات المطلوبة
A12: المبيعات الخارجية | B12: outside-sales | C12: =COUNTIF('طلبات الخدمة · Service'!G:G,"outside-sales")
A13: المبيعات الداخلية | B13: inside-sales | C13: =COUNTIF('طلبات الخدمة · Service'!G:G,"inside-sales")
A14: تطوير المبيعات | B14: sales-development | C14: =COUNTIF('طلبات الخدمة · Service'!G:G,"sales-development")
A15: توليد العملاء المحتملين | B15: lead-generation | C15: =COUNTIF('طلبات الخدمة · Service'!G:G,"lead-generation")
A16: أدوات الذكاء الاصطناعي | B16: ai-sales | C16: =COUNTIF('طلبات الخدمة · Service'!G:G,"ai-sales")
A18: خدمات وباقات المسوقين
A19: تحسين الظهور في محركات البحث | B19: seo | C19: =COUNTIF('المسوقين · Marketers'!H:H,"seo")
A20: إدارة الحملات الإعلانية | B20: campaigns | C20: =COUNTIF('المسوقين · Marketers'!H:H,"campaigns")
A21: الباقة الأساسية | B21: basic | C21: =COUNTIF('المسوقين · Marketers'!H:H,"basic")
A22: الباقة الاحترافية | B22: pro | C22: =COUNTIF('المسوقين · Marketers'!H:H,"pro")

Sheet الاستشارات · Contact
A1: التاريخ والوقت / Timestamp | B1: رقم الطلب / Submission ID | C1: الاسم / Name | D1: رقم الجوال / Phone | E1: الايميل / Email | F1: الرسالة / Message | G1: اللغة / Language | H1: الصفحة / Page | I1: المصدر المُحيل / Referrer | J1: utm_source | K1: utm_medium | L1: utm_campaign | M1: الجهاز والمتصفح / Device | N1: حالة CRM / CRM status | O1: معرّف Bigin / Bigin ID | P1: حالة المتابعة / Follow-up | Q1: المسؤول / Owner | R1: ملاحظات الفريق / Team notes

Sheet طلبات الخدمة · Service
A1: التاريخ والوقت / Timestamp | B1: رقم الطلب / Submission ID | C1: الاسم / Name | D1: رقم الجوال / Phone | E1: الايميل / Email | F1: الخدمة / Service | G1: رمز الخدمة / Service slug | H1: اسم الجهة / Company | I1: ملاحظات العميل / Notes | J1: اللغة / Language | K1: الصفحة / Page | L1: المصدر المُحيل / Referrer | M1: utm_source | N1: utm_medium | O1: utm_campaign | P1: الجهاز والمتصفح / Device | Q1: حالة CRM / CRM status | R1: معرّف Bigin / Bigin ID | S1: حالة المتابعة / Follow-up | T1: المسؤول / Owner | U1: ملاحظات الفريق / Team notes

Sheet المسوقين · Marketers
A1: التاريخ والوقت / Timestamp | B1: رقم الطلب / Submission ID | C1: الاسم / Name | D1: رقم الجوال / Phone | E1: الايميل / Email | F1: النوع / Type | G1: الباقة أو الخدمة / Choice | H1: رمز الاختيار / Choice slug | I1: رابط المنتج / Product link | J1: ملاحظات العميل / Notes | K1: اللغة / Language | L1: الصفحة / Page | M1: المصدر المُحيل / Referrer | N1: utm_source | O1: utm_medium | P1: utm_campaign | Q1: الجهاز والمتصفح / Device | R1: حالة CRM / CRM status | S1: معرّف Bigin / Bigin ID | T1: حالة المتابعة / Follow-up | U1: المسؤول / Owner | V1: ملاحظات الفريق / Team notes

Sheet التوظيف · Jobs
A1: التاريخ والوقت / Timestamp | B1: رقم الطلب / Submission ID | C1: الاسم / Name | D1: رقم الجوال / Phone | E1: الايميل / Email | F1: الوظيفة / Role | G1: رمز الوظيفة / Role slug | H1: لينكدإن / LinkedIn | I1: السيرة الذاتية / CV link | J1: ملف الأعمال / Portfolio | K1: نبذة عن المتقدم / About | L1: اللغة / Language | M1: الصفحة / Page | N1: المصدر المُحيل / Referrer | O1: utm_source | P1: utm_medium | Q1: utm_campaign | R1: الجهاز والمتصفح / Device | S1: حالة CRM / CRM status | T1: معرّف Bigin / Bigin ID | U1: حالة المتابعة / Follow-up | V1: المسؤول / Owner | W1: ملاحظات الفريق / Team notes

Sheet الحقول · Fields
A1: التبويب / Sheet | B1: قيمة form في الطلب | C1: العمود | D1: عنوان العمود | E1: حقل التطبيق / App field | F1: الحالة | G1: مثال
A2: الاستشارات · Contact | B2: contact | D2: الصفحة الرئيسية — قسم «تواصل معنا» (/)
C3: A | D3: التاريخ والوقت / Timestamp | E3: (الخادم) وقت الاستلام | F3: تلقائي | G3: 2026-08-07 14:32
C4: B | D4: رقم الطلب / Submission ID | E4: (الخادم) معرّف فريد | F4: تلقائي | G4: SU-4F2A9C31
C5: C | D5: الاسم / Name | E5: name | F5: إلزامي | G5: محمد العتيبي
C6: D | D6: رقم الجوال / Phone | E6: phone | F6: إلزامي | G6: 0551234567
C7: E | D7: الايميل / Email | E7: email | F7: اختياري | G7: m@example.com
C8: F | D8: الرسالة / Message | E8: message | F8: اختياري | G8: أبغى استشارة لفريق مبيعات
C9: G | D9: اللغة / Language | E9: (الموقع) لغة العرض | F9: تلقائي | G9: ar
C10: H | D10: الصفحة / Page | E10: (الموقع) مسار الصفحة | F10: تلقائي | G10: /
C11: I | D11: المصدر المُحيل / Referrer | E11: (الموقع) الصفحة السابقة | F11: تلقائي | G11: https://google.com/
C12: J | D12: utm_source | E12: (الرابط) utm_source | F12: تلقائي | G12: google
C13: K | D13: utm_medium | E13: (الرابط) utm_medium | F13: تلقائي | G13: cpc
C14: L | D14: utm_campaign | E14: (الرابط) utm_campaign | F14: تلقائي | G14: summer-sales
... C20: R | D20: ملاحظات الفريق / Team notes | E20: — يعبّيه الفريق | F20: يدوي | G20: موعد مكالمة الأحد
A22: طلبات الخدمة · Service | B22: service-request | D22: صفحة الخدمات وصفحات الخدمة (/services · /services/:slug)
C23: A | D23: التاريخ والوقت / Timestamp | E23: (الخادم) وقت الاستلام | F23: تلقائي | G23: 2026-08-07 14:32
C24: B | D24: رقم الطلب / Submission ID | E24: (الخادم) معرّف فريد | F24: تلقائي | G24: SU-4F2A9C31
C25: C | D25: الاسم / Name | E25: name | F25: إلزامي | G25: محمد العتيبي
C26: D | D26: رقم الجوال / Phone | E26: phone | F26: إلزامي | G26: 0551234567
C27: E | D27: الايميل / Email | E27: email | F27: اختياري | G27: m@example.com
C28: F | D28: الخدمة / Service | E28: serviceLabel | F28: إلزامي | G28: المبيعات الداخلية
C29: G | D29: رمز الخدمة / Service slug | E29: service | F29: إلزامي | G29: inside-sales
C30: H | D30: اسم الجهة / Company | E30: org | F30: اختياري | G30: شركة نُزُل
C31: I | D31: ملاحظات العميل / Notes | E31: notes | F31: اختياري | G31: نحتاج البدء الشهر الجاي
C32: J | D32: اللغة / Language | E32: (الموقع) لغة العرض | F32: تلقائي | G32: ar
C33: K | D33: الصفحة / Page | E33: (الموقع) مسار الصفحة | F33: تلقائي | G33: /services/inside-sales
C34: L | D34: المصدر المُحيل / Referrer | E34: (الموقع) الصفحة السابقة | F34: تلقائي | G34: https://google.com/
... C43: U | D43: ملاحظات الفريق / Team notes | E43: — يعبّيه الفريق | F43: يدوي | G43: موعد مكالمة الأحد
A45: المسوقين · Marketers | B45: marketers-apply | D45: صفحة التسويق — نموذج التقديم (/marketers?type=…&pick=…)
C46: A | D46: التاريخ والوقت / Timestamp | E46: (الخادم) وقت الاستلام | F46: تلقائي | G46: 2026-08-07 14:32
C47: B | D47: رقم الطلب / Submission ID | E47: (الخادم) معرّف فريد | F47: تلقائي | G47: SU-4F2A9C31
C48: C | D48: الاسم / Name | E48: name | F48: إلزامي | G48: محمد العتيبي
C49: D | D49: رقم الجوال / Phone | E49: phone | F49: إلزامي | G49: 0551234567
C50: E | D50: الايميل / Email | E50: email | F50: اختياري | G50: m@example.com
C51: F | D51: النوع / Type | E51: planType | F51: تلقائي | G51: باقات المسوقين
C52: G | D52: الباقة أو الخدمة / Choice | E52: planLabel | F52: إلزامي | G52: الباقة الاحترافية
C53: H | D53: رمز الاختيار / Choice slug | E53: plan | F53: إلزامي | G53: pro
C54: I | D54: رابط المنتج / Product link | E54: link | F54: إلزامي | G54: https://example.com
C55: J | D55: ملاحظات العميل / Notes | E55: notes | F55: اختياري | G55: نحتاج البدء الشهر الجاي
...
